[2025-10-29T01:10:44.069+0000] {taskinstance.py:1159} INFO - Dependencies all met for dep_context=non-requeueable deps ti=<TaskInstance: diabetes_training_pipeline.train_models scheduled__2025-10-01T00:00:00+00:00 [queued]>
[2025-10-29T01:10:44.163+0000] {taskinstance.py:1159} INFO - Dependencies all met for dep_context=requeueable deps ti=<TaskInstance: diabetes_training_pipeline.train_models scheduled__2025-10-01T00:00:00+00:00 [queued]>
[2025-10-29T01:10:44.163+0000] {taskinstance.py:1361} INFO - Starting attempt 1 of 2
[2025-10-29T01:10:44.176+0000] {taskinstance.py:1382} INFO - Executing <Task(PythonOperator): train_models> on 2025-10-01 00:00:00+00:00
[2025-10-29T01:10:44.190+0000] {standard_task_runner.py:57} INFO - Started process 1950 to run task
[2025-10-29T01:10:44.196+0000] {standard_task_runner.py:84} INFO - Running: ['***', 'tasks', 'run', 'diabetes_training_pipeline', 'train_models', 'scheduled__2025-10-01T00:00:00+00:00', '--job-id', '14', '--raw', '--subdir', 'DAGS_FOLDER/diabetes_training_pipeline.py', '--cfg-path', '/tmp/tmpf2c6fsc7']
[2025-10-29T01:10:44.202+0000] {standard_task_runner.py:85} INFO - Job 14: Subtask train_models
[2025-10-29T01:10:44.274+0000] {task_command.py:416} INFO - Running <TaskInstance: diabetes_training_pipeline.train_models scheduled__2025-10-01T00:00:00+00:00 [running]> on host 8f23d0ceb5b8
[2025-10-29T01:10:44.369+0000] {taskinstance.py:1662} INFO - Exporting env vars: AIRFLOW_CTX_DAG_OWNER='mlops_team' AIRFLOW_CTX_DAG_ID='diabetes_training_pipeline' AIRFLOW_CTX_TASK_ID='train_models' AIRFLOW_CTX_EXECUTION_DATE='2025-10-01T00:00:00+00:00' AIRFLOW_CTX_TRY_NUMBER='1' AIRFLOW_CTX_DAG_RUN_ID='scheduled__2025-10-01T00:00:00+00:00'
[2025-10-29T01:10:46.721+0000] {logging_mixin.py:154} WARNING - 2025/10/29 01:10:46 INFO mlflow.tracking.fluent: Experiment with name 'diabetes_readmission_stage2' does not exist. Creating a new experiment.
[2025-10-29T01:10:47.098+0000] {taskinstance.py:1937} ERROR - Task failed with exception
Traceback (most recent call last):
  File "/home/airflow/.local/lib/python3.10/site-packages/airflow/operators/python.py", line 192, in execute
    return_value = self.execute_callable()
  File "/home/airflow/.local/lib/python3.10/site-packages/airflow/operators/python.py", line 209, in execute_callable
    return self.python_callable(*self.op_args, **self.op_kwargs)
  File "/opt/airflow/dags/diabetes_training_pipeline.py", line 103, in train_models
    mlflow.set_experiment(EXPERIMENT_NAME)
  File "/home/airflow/.local/lib/python3.10/site-packages/mlflow/tracking/fluent.py", line 144, in set_experiment
    experiment_id = client.create_experiment(experiment_name)
  File "/home/airflow/.local/lib/python3.10/site-packages/mlflow/tracking/client.py", line 570, in create_experiment
    return self._tracking_client.create_experiment(name, artifact_location, tags)
  File "/home/airflow/.local/lib/python3.10/site-packages/mlflow/tracking/_tracking_service/client.py", line 235, in create_experiment
    return self.store.create_experiment(
  File "/home/airflow/.local/lib/python3.10/site-packages/mlflow/store/tracking/rest_store.py", line 98, in create_experiment
    response_proto = self._call_endpoint(CreateExperiment, req_body)
  File "/home/airflow/.local/lib/python3.10/site-packages/mlflow/store/tracking/rest_store.py", line 59, in _call_endpoint
    return call_endpoint(self.get_host_creds(), endpoint, method, json_body, response_proto)
  File "/home/airflow/.local/lib/python3.10/site-packages/mlflow/utils/rest_utils.py", line 219, in call_endpoint
    response = verify_rest_response(response, endpoint)
  File "/home/airflow/.local/lib/python3.10/site-packages/mlflow/utils/rest_utils.py", line 151, in verify_rest_response
    raise RestException(json.loads(response.text))
mlflow.exceptions.RestException: RESOURCE_ALREADY_EXISTS: Experiment(name=diabetes_readmission_stage2) already exists. Error: (raised as a result of Query-invoked autoflush; consider using a session.no_autoflush block if this flush is occurring prematurely)
(pymysql.err.IntegrityError) (1062, "Duplicate entry 'diabetes_readmission_stage2' for key 'experiments.name'")
[SQL: INSERT INTO experiments (name, artifact_location, lifecycle_stage, creation_time, last_update_time) VALUES (%(name)s, %(artifact_location)s, %(lifecycle_stage)s, %(creation_time)s, %(last_update_time)s)]
[parameters: {'name': 'diabetes_readmission_stage2', 'artifact_location': '', 'lifecycle_stage': 'active', 'creation_time': 1761700246837, 'last_update_time': 1761700246837}]
(Background on this error at: https://sqlalche.me/e/20/gkpj)
[2025-10-29T01:10:47.129+0000] {taskinstance.py:1400} INFO - Marking task as UP_FOR_RETRY. dag_id=diabetes_training_pipeline, task_id=train_models, execution_date=20251001T000000, start_date=20251029T011044, end_date=20251029T011047
[2025-10-29T01:10:47.153+0000] {standard_task_runner.py:104} ERROR - Failed to execute job 14 for task train_models (RESOURCE_ALREADY_EXISTS: Experiment(name=diabetes_readmission_stage2) already exists. Error: (raised as a result of Query-invoked autoflush; consider using a session.no_autoflush block if this flush is occurring prematurely)
(pymysql.err.IntegrityError) (1062, "Duplicate entry 'diabetes_readmission_stage2' for key 'experiments.name'")
[SQL: INSERT INTO experiments (name, artifact_location, lifecycle_stage, creation_time, last_update_time) VALUES (%(name)s, %(artifact_location)s, %(lifecycle_stage)s, %(creation_time)s, %(last_update_time)s)]
[parameters: {'name': 'diabetes_readmission_stage2', 'artifact_location': '', 'lifecycle_stage': 'active', 'creation_time': 1761700246837, 'last_update_time': 1761700246837}]
(Background on this error at: https://sqlalche.me/e/20/gkpj); 1950)
[2025-10-29T01:10:47.206+0000] {local_task_job_runner.py:228} INFO - Task exited with return code 1
[2025-10-29T01:10:47.263+0000] {taskinstance.py:2778} INFO - 0 downstream tasks scheduled from follow-on schedule check
