[2025-10-29T01:12:48.434+0000] {taskinstance.py:1159} INFO - Dependencies all met for dep_context=non-requeueable deps ti=<TaskInstance: diabetes_training_pipeline.train_models scheduled__2025-10-01T00:00:00+00:00 [queued]>
[2025-10-29T01:12:48.513+0000] {taskinstance.py:1159} INFO - Dependencies all met for dep_context=requeueable deps ti=<TaskInstance: diabetes_training_pipeline.train_models scheduled__2025-10-01T00:00:00+00:00 [queued]>
[2025-10-29T01:12:48.513+0000] {taskinstance.py:1361} INFO - Starting attempt 2 of 2
[2025-10-29T01:12:48.520+0000] {taskinstance.py:1382} INFO - Executing <Task(PythonOperator): train_models> on 2025-10-01 00:00:00+00:00
[2025-10-29T01:12:48.530+0000] {standard_task_runner.py:57} INFO - Started process 2216 to run task
[2025-10-29T01:12:48.534+0000] {standard_task_runner.py:84} INFO - Running: ['***', 'tasks', 'run', 'diabetes_training_pipeline', 'train_models', 'scheduled__2025-10-01T00:00:00+00:00', '--job-id', '18', '--raw', '--subdir', 'DAGS_FOLDER/diabetes_training_pipeline.py', '--cfg-path', '/tmp/tmp0qa4se2c']
[2025-10-29T01:12:48.544+0000] {standard_task_runner.py:85} INFO - Job 18: Subtask train_models
[2025-10-29T01:12:48.582+0000] {task_command.py:416} INFO - Running <TaskInstance: diabetes_training_pipeline.train_models scheduled__2025-10-01T00:00:00+00:00 [running]> on host 8f23d0ceb5b8
[2025-10-29T01:12:48.629+0000] {taskinstance.py:1662} INFO - Exporting env vars: AIRFLOW_CTX_DAG_OWNER='mlops_team' AIRFLOW_CTX_DAG_ID='diabetes_training_pipeline' AIRFLOW_CTX_TASK_ID='train_models' AIRFLOW_CTX_EXECUTION_DATE='2025-10-01T00:00:00+00:00' AIRFLOW_CTX_TRY_NUMBER='2' AIRFLOW_CTX_DAG_RUN_ID='scheduled__2025-10-01T00:00:00+00:00'
[2025-10-29T01:12:50.147+0000] {logging_mixin.py:154} WARNING - 2025/10/29 01:12:50 WARNING mlflow.utils.git_utils: Failed to import Git (the Git executable is probably not on your PATH), so Git SHA is not available. Error: Failed to initialize: Bad git executable.
The git executable must be specified in one of the following ways:
    - be included in your $PATH
    - be set via $GIT_PYTHON_GIT_EXECUTABLE
    - explicitly set via git.refresh(<full-path-to-git-executable>)

All git commands will error until this is rectified.

This initial message can be silenced or aggravated in the future by setting the
$GIT_PYTHON_REFRESH environment variable. Use one of the following values:
    - quiet|q|silence|s|silent|none|n|0: for no message or exception
    - warn|w|warning|log|l|1: for a warning message (logging level CRITICAL, displayed by default)
    - error|e|exception|raise|r|2: for a raised exception

Example:
    export GIT_PYTHON_REFRESH=quiet
[2025-10-29T01:12:54.331+0000] {logging_mixin.py:154} WARNING - 2025/10/29 01:12:54 WARNING mlflow.models.signature: Failed to infer the model signature from the input example. Reason: MlflowException("Unable to map 'object' type to MLflow DataType. object can be mapped iff all values have identical data type which is one of (string, (bytes or byterray),  int, float)."). To see the full traceback, set the logging level to DEBUG via `logging.getLogger("mlflow").setLevel(logging.DEBUG)`. To disable automatic signature inference, set `signature` to `False` in your `log_model` or `save_model` call.
[2025-10-29T01:12:56.875+0000] {logging_mixin.py:154} WARNING - /home/***/.local/lib/python3.10/site-packages/_distutils_hack/__init__.py:33 UserWarning: Setuptools is replacing distutils.
[2025-10-29T01:12:56.985+0000] {credentials.py:1147} INFO - Found credentials in environment variables.
[2025-10-29T01:12:57.610+0000] {logging_mixin.py:154} WARNING - Registered model 'diabetes_readmit_logreg' already exists. Creating a new version of this model...
[2025-10-29T01:12:57.668+0000] {logging_mixin.py:154} WARNING - 2025/10/29 01:12:57 INFO mlflow.store.model_registry.abstract_store: Waiting up to 300 seconds for model version to finish creation. Model name: diabetes_readmit_logreg, version 2
[2025-10-29T01:12:57.668+0000] {logging_mixin.py:154} WARNING - Created version '2' of model 'diabetes_readmit_logreg'.
[2025-10-29T01:13:08.482+0000] {logging_mixin.py:154} WARNING - 2025/10/29 01:13:08 WARNING mlflow.models.signature: Failed to infer the model signature from the input example. Reason: MlflowException("Unable to map 'object' type to MLflow DataType. object can be mapped iff all values have identical data type which is one of (string, (bytes or byterray),  int, float)."). To see the full traceback, set the logging level to DEBUG via `logging.getLogger("mlflow").setLevel(logging.DEBUG)`. To disable automatic signature inference, set `signature` to `False` in your `log_model` or `save_model` call.
[2025-10-29T01:13:10.162+0000] {logging_mixin.py:154} WARNING - Registered model 'diabetes_readmit_gb' already exists. Creating a new version of this model...
[2025-10-29T01:13:10.200+0000] {logging_mixin.py:154} WARNING - 2025/10/29 01:13:10 INFO mlflow.store.model_registry.abstract_store: Waiting up to 300 seconds for model version to finish creation. Model name: diabetes_readmit_gb, version 2
[2025-10-29T01:13:10.200+0000] {logging_mixin.py:154} WARNING - Created version '2' of model 'diabetes_readmit_gb'.
[2025-10-29T01:13:25.553+0000] {logging_mixin.py:154} WARNING - /home/***/.local/lib/python3.10/site-packages/sklearn/ensemble/_base.py:214 UserWarning: Loky-backed parallel loops cannot be called in a multiprocessing, setting n_jobs=1
[2025-10-29T01:13:26.128+0000] {logging_mixin.py:154} WARNING - /home/***/.local/lib/python3.10/site-packages/sklearn/ensemble/_base.py:214 UserWarning: Loky-backed parallel loops cannot be called in a multiprocessing, setting n_jobs=1
[2025-10-29T01:13:26.710+0000] {logging_mixin.py:154} WARNING - /home/***/.local/lib/python3.10/site-packages/sklearn/ensemble/_base.py:214 UserWarning: Loky-backed parallel loops cannot be called in a multiprocessing, setting n_jobs=1
[2025-10-29T01:13:27.210+0000] {logging_mixin.py:154} WARNING - /home/***/.local/lib/python3.10/site-packages/sklearn/ensemble/_base.py:214 UserWarning: Loky-backed parallel loops cannot be called in a multiprocessing, setting n_jobs=1
[2025-10-29T01:13:27.717+0000] {logging_mixin.py:154} WARNING - 2025/10/29 01:13:27 WARNING mlflow.models.signature: Failed to infer the model signature from the input example. Reason: MlflowException("Unable to map 'object' type to MLflow DataType. object can be mapped iff all values have identical data type which is one of (string, (bytes or byterray),  int, float)."). To see the full traceback, set the logging level to DEBUG via `logging.getLogger("mlflow").setLevel(logging.DEBUG)`. To disable automatic signature inference, set `signature` to `False` in your `log_model` or `save_model` call.
[2025-10-29T01:13:31.936+0000] {local_task_job_runner.py:228} INFO - Task exited with return code -9
[2025-10-29T01:13:32.048+0000] {taskinstance.py:2778} INFO - 0 downstream tasks scheduled from follow-on schedule check
